2025-03-16 01:32:50,144 - Config - INFO - 当前配置：{
  "id": 12345678,
  "mode": "CO",
  "keepalive_timeout": 1,
  "zmq": {
    "in_port": 13416,
    "out_port": 13415,
    "max_cache": 1000
  },
  "ros": {
    "pointcloud_topic": "pcd_topic1",
    "queue_size": 10
  },
  "processing": {
    "interval": 1,
    "max_workers": 4,
    "overlap_threshold": 0.3,
    "H": 100,
    "W": 100
  }
}
2025-03-16 01:32:50,145 - asyncio - DEBUG - Using selector: EpollSelector
2025-03-16 01:32:50,146 - rosout - DEBUG - signal handlers for rospy disabled
2025-03-16 01:32:50,294 - ZMQ - INFO - ZMQ接收循环启动
2025-03-16 01:32:50,294 - ROS - INFO - 启动ROS线程
2025-03-16 01:32:50,296 - asyncio - ERROR - Task exception was never retrieved
future: <Task finished name='Task-6' coro=<CollaborationSystem.pipeline() done, defined at co/main.py:61> exception=RuntimeError("Task <Task pending name='Task-6' coro=<CollaborationSystem.pipeline() running at co/main.py:62>> got Future <Future pending> attached to a different loop")>
Traceback (most recent call last):
  File "co/main.py", line 62, in pipeline
    base_data_dict = await self.base_data_retriever()
  File "/home/nvidia/mydisk/gzh/projects/cosense/co/baseDataRetriever.py", line 51, in __call__
    data_dict[CONFIG['id']] = await self.get_ego_data()
  File "/home/nvidia/mydisk/gzh/projects/cosense/co/baseDataRetriever.py", line 14, in get_ego_data
    "lidar_np": await agent_server.wait_ego_pcd(),
  File "/home/nvidia/mydisk/gzh/projects/cosense/co/server.py", line 150, in wait_ego_pcd
    await self.ego_pcd.wait()
  File "/home/nvidia/mydisk/gzh/projects/cosense/co/utils.py", line 37, in wait
    await self._wait_condition(timeout)
  File "/home/nvidia/mydisk/gzh/projects/cosense/co/utils.py", line 64, in _wait_condition
    await self._condition.wait_for(lambda: self._value is not None)
  File "/home/nvidia/mydisk/miniconda3/envs/rospy/lib/python3.8/asyncio/locks.py", line 400, in wait_for
    await self.wait()
  File "/home/nvidia/mydisk/miniconda3/envs/rospy/lib/python3.8/asyncio/locks.py", line 373, in wait
    await fut
RuntimeError: Task <Task pending name='Task-6' coro=<CollaborationSystem.pipeline() running at co/main.py:62>> got Future <Future pending> attached to a different loop
2025-03-16 01:32:50,297 - rospy.topics - DEBUG - tm._add: /pcd_topic1, sensor_msgs/PointCloud2, sub
2025-03-16 01:32:50,298 - rospy.registration - DEBUG - master.registerSubscriber(/async_ros_node, /pcd_topic1, sensor_msgs/PointCloud2, http://miivii-tegra:36455/)
2025-03-16 01:32:50,300 - rospy.impl.masterslave - DEBUG - connect[/pcd_topic1]: calling requestTopic(/async_ros_node, /pcd_topic1, [['TCPROS']])
2025-03-16 01:32:50,302 - rospy.impl.masterslave - DEBUG - requestTopic('/rosout', '/rosout', [['TCPROS']])
2025-03-16 01:32:50,303 - rospy.impl.masterslave - DEBUG - requestTopic[/rosout]: choosing protocol TCPROS
2025-03-16 01:32:50,303 - rospy.impl.masterslave - DEBUG - connect[/pcd_topic1]: requestTopic returned protocol list ['TCPROS', 'miivii-tegra', 33081]
2025-03-16 01:32:50,303 - rospy.impl.masterslave - DEBUG - requestTopic('/rosout', '/rosout', [['TCPROS']]) returns (1, 'ready on miivii-tegra:45807', ['TCPROS', 'miivii-tegra', 45807])
2025-03-16 01:32:50,303 - rospy.internal - INFO - topic[/pcd_topic1] adding connection to [http://miivii-tegra:34121/], count 0
2025-03-16 01:32:50,306 - rospy.tcpros - DEBUG - [/pcd_topic1]: writing header
2025-03-16 01:32:50,306 - rospy.tcpros - DEBUG - receive_loop for [/pcd_topic1]
2025-03-16 01:32:50,404 - rospy.impl.masterslave - DEBUG - shutdown('/master', '[/async_ros_node] Reason: new node registered with same name')
2025-03-16 01:32:50,405 - rospy.tcpros - DEBUG - [/rosout]: writing header
2025-03-16 01:32:50,405 - rospy.impl.masterslave - INFO - external shutdown request from [/master]: [/async_ros_node] Reason: new node registered with same name
2025-03-16 01:32:50,406 - rospy.core - INFO - signal_shutdown [external shutdown request from [/master]: [[/async_ros_node] Reason: new node registered with same name]]
2025-03-16 01:32:50,406 - rospy.internal - INFO - topic[/rosout] adding connection to [/rosout], count 0
2025-03-16 01:32:50,406 - rospy.registration - DEBUG - registration cleanup starting
2025-03-16 01:32:50,407 - rospy.registration - DEBUG - unregisterSubscriber [/pcd_topic1]
2025-03-16 01:32:50,407 - rospy.registration - DEBUG - unregisterPublisher [/rosout]
2025-03-16 01:32:50,407 - rospy.registration - DEBUG - unregisterService [/async_ros_node/get_loggers]
2025-03-16 01:32:50,407 - rospy.registration - DEBUG - unregisterService [/async_ros_node/set_logger_level]
2025-03-16 01:32:50,409 - rospy.registration - DEBUG - registration cleanup: master calls complete
2025-03-16 01:32:50,410 - rospy.internal - INFO - topic[/rosout] removing connection to /rosout
2025-03-16 01:32:50,410 - rospy.internal - INFO - topic[/pcd_topic1] removing connection to http://miivii-tegra:34121/
2025-03-16 01:32:50,411 - rospy.internal - DEBUG - [/pcd_topic1] failed to receive incoming message: Traceback (most recent call last):
  File "/opt/ros/noetic/lib/python3/dist-packages/rospy/impl/tcpros_base.py", line 804, in receive_loop
    msgs = self.receive_once()
  File "/opt/ros/noetic/lib/python3/dist-packages/rospy/impl/tcpros_base.py", line 744, in receive_once
    self.stat_bytes += recv_buff(sock, b, p.buff_size)
  File "/opt/ros/noetic/lib/python3/dist-packages/rospy/impl/tcpros_base.py", line 111, in recv_buff
    raise TransportTerminated("unable to receive data from sender, check sender's logs for details")
rospy.exceptions.TransportTerminated: unable to receive data from sender, check sender's logs for details

2025-03-16 01:32:50,411 - rospy.internal - DEBUG - receive_loop[/pcd_topic1]: done condition met, exited loop
2025-03-16 01:32:50,512 - rospy.impl.masterslave - DEBUG - shutdown('/master', '[/async_ros_node] Reason: new node registered with same name') returns (1, 'shutdown', 0)
2025-03-16 01:32:51,297 - asyncio - ERROR - Task exception was never retrieved
future: <Task finished name='Task-7' coro=<CollaborationSystem.pipeline() done, defined at co/main.py:61> exception=RuntimeError("Task <Task pending name='Task-7' coro=<CollaborationSystem.pipeline() running at co/main.py:62>> got Future <Future pending> attached to a different loop")>
Traceback (most recent call last):
  File "co/main.py", line 62, in pipeline
    base_data_dict = await self.base_data_retriever()
  File "/home/nvidia/mydisk/gzh/projects/cosense/co/baseDataRetriever.py", line 51, in __call__
    data_dict[CONFIG['id']] = await self.get_ego_data()
  File "/home/nvidia/mydisk/gzh/projects/cosense/co/baseDataRetriever.py", line 14, in get_ego_data
    "lidar_np": await agent_server.wait_ego_pcd(),
  File "/home/nvidia/mydisk/gzh/projects/cosense/co/server.py", line 150, in wait_ego_pcd
    await self.ego_pcd.wait()
  File "/home/nvidia/mydisk/gzh/projects/cosense/co/utils.py", line 37, in wait
    await self._wait_condition(timeout)
  File "/home/nvidia/mydisk/gzh/projects/cosense/co/utils.py", line 64, in _wait_condition
    await self._condition.wait_for(lambda: self._value is not None)
  File "/home/nvidia/mydisk/miniconda3/envs/rospy/lib/python3.8/asyncio/locks.py", line 400, in wait_for
    await self.wait()
  File "/home/nvidia/mydisk/miniconda3/envs/rospy/lib/python3.8/asyncio/locks.py", line 373, in wait
    await fut
RuntimeError: Task <Task pending name='Task-7' coro=<CollaborationSystem.pipeline() running at co/main.py:62>> got Future <Future pending> attached to a different loop
2025-03-16 01:32:52,299 - asyncio - ERROR - Task exception was never retrieved
future: <Task finished name='Task-8' coro=<CollaborationSystem.pipeline() done, defined at co/main.py:61> exception=RuntimeError("Task <Task pending name='Task-8' coro=<CollaborationSystem.pipeline() running at co/main.py:62>> got Future <Future pending> attached to a different loop")>
Traceback (most recent call last):
  File "co/main.py", line 62, in pipeline
    base_data_dict = await self.base_data_retriever()
  File "/home/nvidia/mydisk/gzh/projects/cosense/co/baseDataRetriever.py", line 51, in __call__
    data_dict[CONFIG['id']] = await self.get_ego_data()
  File "/home/nvidia/mydisk/gzh/projects/cosense/co/baseDataRetriever.py", line 14, in get_ego_data
    "lidar_np": await agent_server.wait_ego_pcd(),
  File "/home/nvidia/mydisk/gzh/projects/cosense/co/server.py", line 150, in wait_ego_pcd
    await self.ego_pcd.wait()
  File "/home/nvidia/mydisk/gzh/projects/cosense/co/utils.py", line 37, in wait
    await self._wait_condition(timeout)
  File "/home/nvidia/mydisk/gzh/projects/cosense/co/utils.py", line 64, in _wait_condition
    await self._condition.wait_for(lambda: self._value is not None)
  File "/home/nvidia/mydisk/miniconda3/envs/rospy/lib/python3.8/asyncio/locks.py", line 400, in wait_for
    await self.wait()
  File "/home/nvidia/mydisk/miniconda3/envs/rospy/lib/python3.8/asyncio/locks.py", line 373, in wait
    await fut
RuntimeError: Task <Task pending name='Task-8' coro=<CollaborationSystem.pipeline() running at co/main.py:62>> got Future <Future pending> attached to a different loop
2025-03-16 01:32:53,302 - asyncio - ERROR - Task exception was never retrieved
future: <Task finished name='Task-9' coro=<CollaborationSystem.pipeline() done, defined at co/main.py:61> exception=RuntimeError("Task <Task pending name='Task-9' coro=<CollaborationSystem.pipeline() running at co/main.py:62>> got Future <Future pending> attached to a different loop")>
Traceback (most recent call last):
  File "co/main.py", line 62, in pipeline
    base_data_dict = await self.base_data_retriever()
  File "/home/nvidia/mydisk/gzh/projects/cosense/co/baseDataRetriever.py", line 51, in __call__
    data_dict[CONFIG['id']] = await self.get_ego_data()
  File "/home/nvidia/mydisk/gzh/projects/cosense/co/baseDataRetriever.py", line 14, in get_ego_data
    "lidar_np": await agent_server.wait_ego_pcd(),
  File "/home/nvidia/mydisk/gzh/projects/cosense/co/server.py", line 150, in wait_ego_pcd
    await self.ego_pcd.wait()
  File "/home/nvidia/mydisk/gzh/projects/cosense/co/utils.py", line 37, in wait
    await self._wait_condition(timeout)
  File "/home/nvidia/mydisk/gzh/projects/cosense/co/utils.py", line 64, in _wait_condition
    await self._condition.wait_for(lambda: self._value is not None)
  File "/home/nvidia/mydisk/miniconda3/envs/rospy/lib/python3.8/asyncio/locks.py", line 400, in wait_for
    await self.wait()
  File "/home/nvidia/mydisk/miniconda3/envs/rospy/lib/python3.8/asyncio/locks.py", line 373, in wait
    await fut
RuntimeError: Task <Task pending name='Task-9' coro=<CollaborationSystem.pipeline() running at co/main.py:62>> got Future <Future pending> attached to a different loop
2025-03-16 01:32:54,303 - asyncio - ERROR - Task exception was never retrieved
future: <Task finished name='Task-10' coro=<CollaborationSystem.pipeline() done, defined at co/main.py:61> exception=RuntimeError("Task <Task pending name='Task-10' coro=<CollaborationSystem.pipeline() running at co/main.py:62>> got Future <Future pending> attached to a different loop")>
Traceback (most recent call last):
  File "co/main.py", line 62, in pipeline
    base_data_dict = await self.base_data_retriever()
  File "/home/nvidia/mydisk/gzh/projects/cosense/co/baseDataRetriever.py", line 51, in __call__
    data_dict[CONFIG['id']] = await self.get_ego_data()
  File "/home/nvidia/mydisk/gzh/projects/cosense/co/baseDataRetriever.py", line 14, in get_ego_data
    "lidar_np": await agent_server.wait_ego_pcd(),
  File "/home/nvidia/mydisk/gzh/projects/cosense/co/server.py", line 150, in wait_ego_pcd
    await self.ego_pcd.wait()
  File "/home/nvidia/mydisk/gzh/projects/cosense/co/utils.py", line 37, in wait
    await self._wait_condition(timeout)
  File "/home/nvidia/mydisk/gzh/projects/cosense/co/utils.py", line 64, in _wait_condition
    await self._condition.wait_for(lambda: self._value is not None)
  File "/home/nvidia/mydisk/miniconda3/envs/rospy/lib/python3.8/asyncio/locks.py", line 400, in wait_for
    await self.wait()
  File "/home/nvidia/mydisk/miniconda3/envs/rospy/lib/python3.8/asyncio/locks.py", line 373, in wait
    await fut
RuntimeError: Task <Task pending name='Task-10' coro=<CollaborationSystem.pipeline() running at co/main.py:62>> got Future <Future pending> attached to a different loop
2025-03-16 01:32:55,305 - asyncio - ERROR - Task exception was never retrieved
future: <Task finished name='Task-11' coro=<CollaborationSystem.pipeline() done, defined at co/main.py:61> exception=RuntimeError("Task <Task pending name='Task-11' coro=<CollaborationSystem.pipeline() running at co/main.py:62>> got Future <Future pending> attached to a different loop")>
Traceback (most recent call last):
  File "co/main.py", line 62, in pipeline
    base_data_dict = await self.base_data_retriever()
  File "/home/nvidia/mydisk/gzh/projects/cosense/co/baseDataRetriever.py", line 51, in __call__
    data_dict[CONFIG['id']] = await self.get_ego_data()
  File "/home/nvidia/mydisk/gzh/projects/cosense/co/baseDataRetriever.py", line 14, in get_ego_data
    "lidar_np": await agent_server.wait_ego_pcd(),
  File "/home/nvidia/mydisk/gzh/projects/cosense/co/server.py", line 150, in wait_ego_pcd
    await self.ego_pcd.wait()
  File "/home/nvidia/mydisk/gzh/projects/cosense/co/utils.py", line 37, in wait
    await self._wait_condition(timeout)
  File "/home/nvidia/mydisk/gzh/projects/cosense/co/utils.py", line 64, in _wait_condition
    await self._condition.wait_for(lambda: self._value is not None)
  File "/home/nvidia/mydisk/miniconda3/envs/rospy/lib/python3.8/asyncio/locks.py", line 400, in wait_for
    await self.wait()
  File "/home/nvidia/mydisk/miniconda3/envs/rospy/lib/python3.8/asyncio/locks.py", line 373, in wait
    await fut
RuntimeError: Task <Task pending name='Task-11' coro=<CollaborationSystem.pipeline() running at co/main.py:62>> got Future <Future pending> attached to a different loop
2025-03-16 01:32:56,306 - asyncio - ERROR - Task exception was never retrieved
future: <Task finished name='Task-12' coro=<CollaborationSystem.pipeline() done, defined at co/main.py:61> exception=RuntimeError("Task <Task pending name='Task-12' coro=<CollaborationSystem.pipeline() running at co/main.py:62>> got Future <Future pending> attached to a different loop")>
Traceback (most recent call last):
  File "co/main.py", line 62, in pipeline
    base_data_dict = await self.base_data_retriever()
  File "/home/nvidia/mydisk/gzh/projects/cosense/co/baseDataRetriever.py", line 51, in __call__
    data_dict[CONFIG['id']] = await self.get_ego_data()
  File "/home/nvidia/mydisk/gzh/projects/cosense/co/baseDataRetriever.py", line 14, in get_ego_data
    "lidar_np": await agent_server.wait_ego_pcd(),
  File "/home/nvidia/mydisk/gzh/projects/cosense/co/server.py", line 150, in wait_ego_pcd
    await self.ego_pcd.wait()
  File "/home/nvidia/mydisk/gzh/projects/cosense/co/utils.py", line 37, in wait
    await self._wait_condition(timeout)
  File "/home/nvidia/mydisk/gzh/projects/cosense/co/utils.py", line 64, in _wait_condition
    await self._condition.wait_for(lambda: self._value is not None)
  File "/home/nvidia/mydisk/miniconda3/envs/rospy/lib/python3.8/asyncio/locks.py", line 400, in wait_for
    await self.wait()
  File "/home/nvidia/mydisk/miniconda3/envs/rospy/lib/python3.8/asyncio/locks.py", line 373, in wait
    await fut
RuntimeError: Task <Task pending name='Task-12' coro=<CollaborationSystem.pipeline() running at co/main.py:62>> got Future <Future pending> attached to a different loop
2025-03-16 01:32:57,308 - asyncio - ERROR - Task exception was never retrieved
future: <Task finished name='Task-13' coro=<CollaborationSystem.pipeline() done, defined at co/main.py:61> exception=RuntimeError("Task <Task pending name='Task-13' coro=<CollaborationSystem.pipeline() running at co/main.py:62>> got Future <Future pending> attached to a different loop")>
Traceback (most recent call last):
  File "co/main.py", line 62, in pipeline
    base_data_dict = await self.base_data_retriever()
  File "/home/nvidia/mydisk/gzh/projects/cosense/co/baseDataRetriever.py", line 51, in __call__
    data_dict[CONFIG['id']] = await self.get_ego_data()
  File "/home/nvidia/mydisk/gzh/projects/cosense/co/baseDataRetriever.py", line 14, in get_ego_data
    "lidar_np": await agent_server.wait_ego_pcd(),
  File "/home/nvidia/mydisk/gzh/projects/cosense/co/server.py", line 150, in wait_ego_pcd
    await self.ego_pcd.wait()
  File "/home/nvidia/mydisk/gzh/projects/cosense/co/utils.py", line 37, in wait
    await self._wait_condition(timeout)
  File "/home/nvidia/mydisk/gzh/projects/cosense/co/utils.py", line 64, in _wait_condition
    await self._condition.wait_for(lambda: self._value is not None)
  File "/home/nvidia/mydisk/miniconda3/envs/rospy/lib/python3.8/asyncio/locks.py", line 400, in wait_for
    await self.wait()
  File "/home/nvidia/mydisk/miniconda3/envs/rospy/lib/python3.8/asyncio/locks.py", line 373, in wait
    await fut
RuntimeError: Task <Task pending name='Task-13' coro=<CollaborationSystem.pipeline() running at co/main.py:62>> got Future <Future pending> attached to a different loop
2025-03-16 01:32:58,309 - asyncio - ERROR - Task exception was never retrieved
future: <Task finished name='Task-14' coro=<CollaborationSystem.pipeline() done, defined at co/main.py:61> exception=RuntimeError("Task <Task pending name='Task-14' coro=<CollaborationSystem.pipeline() running at co/main.py:62>> got Future <Future pending> attached to a different loop")>
Traceback (most recent call last):
  File "co/main.py", line 62, in pipeline
    base_data_dict = await self.base_data_retriever()
  File "/home/nvidia/mydisk/gzh/projects/cosense/co/baseDataRetriever.py", line 51, in __call__
    data_dict[CONFIG['id']] = await self.get_ego_data()
  File "/home/nvidia/mydisk/gzh/projects/cosense/co/baseDataRetriever.py", line 14, in get_ego_data
    "lidar_np": await agent_server.wait_ego_pcd(),
  File "/home/nvidia/mydisk/gzh/projects/cosense/co/server.py", line 150, in wait_ego_pcd
    await self.ego_pcd.wait()
  File "/home/nvidia/mydisk/gzh/projects/cosense/co/utils.py", line 37, in wait
    await self._wait_condition(timeout)
  File "/home/nvidia/mydisk/gzh/projects/cosense/co/utils.py", line 64, in _wait_condition
    await self._condition.wait_for(lambda: self._value is not None)
  File "/home/nvidia/mydisk/miniconda3/envs/rospy/lib/python3.8/asyncio/locks.py", line 400, in wait_for
    await self.wait()
  File "/home/nvidia/mydisk/miniconda3/envs/rospy/lib/python3.8/asyncio/locks.py", line 373, in wait
    await fut
RuntimeError: Task <Task pending name='Task-14' coro=<CollaborationSystem.pipeline() running at co/main.py:62>> got Future <Future pending> attached to a different loop
2025-03-16 01:32:59,311 - asyncio - ERROR - Task exception was never retrieved
future: <Task finished name='Task-15' coro=<CollaborationSystem.pipeline() done, defined at co/main.py:61> exception=RuntimeError("Task <Task pending name='Task-15' coro=<CollaborationSystem.pipeline() running at co/main.py:62>> got Future <Future pending> attached to a different loop")>
Traceback (most recent call last):
  File "co/main.py", line 62, in pipeline
    base_data_dict = await self.base_data_retriever()
  File "/home/nvidia/mydisk/gzh/projects/cosense/co/baseDataRetriever.py", line 51, in __call__
    data_dict[CONFIG['id']] = await self.get_ego_data()
  File "/home/nvidia/mydisk/gzh/projects/cosense/co/baseDataRetriever.py", line 14, in get_ego_data
    "lidar_np": await agent_server.wait_ego_pcd(),
  File "/home/nvidia/mydisk/gzh/projects/cosense/co/server.py", line 150, in wait_ego_pcd
    await self.ego_pcd.wait()
  File "/home/nvidia/mydisk/gzh/projects/cosense/co/utils.py", line 37, in wait
    await self._wait_condition(timeout)
  File "/home/nvidia/mydisk/gzh/projects/cosense/co/utils.py", line 64, in _wait_condition
    await self._condition.wait_for(lambda: self._value is not None)
  File "/home/nvidia/mydisk/miniconda3/envs/rospy/lib/python3.8/asyncio/locks.py", line 400, in wait_for
    await self.wait()
  File "/home/nvidia/mydisk/miniconda3/envs/rospy/lib/python3.8/asyncio/locks.py", line 373, in wait
    await fut
RuntimeError: Task <Task pending name='Task-15' coro=<CollaborationSystem.pipeline() running at co/main.py:62>> got Future <Future pending> attached to a different loop
2025-03-16 01:33:00,313 - asyncio - ERROR - Task exception was never retrieved
future: <Task finished name='Task-16' coro=<CollaborationSystem.pipeline() done, defined at co/main.py:61> exception=RuntimeError("Task <Task pending name='Task-16' coro=<CollaborationSystem.pipeline() running at co/main.py:62>> got Future <Future pending> attached to a different loop")>
Traceback (most recent call last):
  File "co/main.py", line 62, in pipeline
    base_data_dict = await self.base_data_retriever()
  File "/home/nvidia/mydisk/gzh/projects/cosense/co/baseDataRetriever.py", line 51, in __call__
    data_dict[CONFIG['id']] = await self.get_ego_data()
  File "/home/nvidia/mydisk/gzh/projects/cosense/co/baseDataRetriever.py", line 14, in get_ego_data
    "lidar_np": await agent_server.wait_ego_pcd(),
  File "/home/nvidia/mydisk/gzh/projects/cosense/co/server.py", line 150, in wait_ego_pcd
    await self.ego_pcd.wait()
  File "/home/nvidia/mydisk/gzh/projects/cosense/co/utils.py", line 37, in wait
    await self._wait_condition(timeout)
  File "/home/nvidia/mydisk/gzh/projects/cosense/co/utils.py", line 64, in _wait_condition
    await self._condition.wait_for(lambda: self._value is not None)
  File "/home/nvidia/mydisk/miniconda3/envs/rospy/lib/python3.8/asyncio/locks.py", line 400, in wait_for
    await self.wait()
  File "/home/nvidia/mydisk/miniconda3/envs/rospy/lib/python3.8/asyncio/locks.py", line 373, in wait
    await fut
RuntimeError: Task <Task pending name='Task-16' coro=<CollaborationSystem.pipeline() running at co/main.py:62>> got Future <Future pending> attached to a different loop
2025-03-16 01:33:01,314 - asyncio - ERROR - Task exception was never retrieved
future: <Task finished name='Task-17' coro=<CollaborationSystem.pipeline() done, defined at co/main.py:61> exception=RuntimeError("Task <Task pending name='Task-17' coro=<CollaborationSystem.pipeline() running at co/main.py:62>> got Future <Future pending> attached to a different loop")>
Traceback (most recent call last):
  File "co/main.py", line 62, in pipeline
    base_data_dict = await self.base_data_retriever()
  File "/home/nvidia/mydisk/gzh/projects/cosense/co/baseDataRetriever.py", line 51, in __call__
    data_dict[CONFIG['id']] = await self.get_ego_data()
  File "/home/nvidia/mydisk/gzh/projects/cosense/co/baseDataRetriever.py", line 14, in get_ego_data
    "lidar_np": await agent_server.wait_ego_pcd(),
  File "/home/nvidia/mydisk/gzh/projects/cosense/co/server.py", line 150, in wait_ego_pcd
    await self.ego_pcd.wait()
  File "/home/nvidia/mydisk/gzh/projects/cosense/co/utils.py", line 37, in wait
    await self._wait_condition(timeout)
  File "/home/nvidia/mydisk/gzh/projects/cosense/co/utils.py", line 64, in _wait_condition
    await self._condition.wait_for(lambda: self._value is not None)
  File "/home/nvidia/mydisk/miniconda3/envs/rospy/lib/python3.8/asyncio/locks.py", line 400, in wait_for
    await self.wait()
  File "/home/nvidia/mydisk/miniconda3/envs/rospy/lib/python3.8/asyncio/locks.py", line 373, in wait
    await fut
RuntimeError: Task <Task pending name='Task-17' coro=<CollaborationSystem.pipeline() running at co/main.py:62>> got Future <Future pending> attached to a different loop
2025-03-16 01:33:02,316 - asyncio - ERROR - Task exception was never retrieved
future: <Task finished name='Task-18' coro=<CollaborationSystem.pipeline() done, defined at co/main.py:61> exception=RuntimeError("Task <Task pending name='Task-18' coro=<CollaborationSystem.pipeline() running at co/main.py:62>> got Future <Future pending> attached to a different loop")>
Traceback (most recent call last):
  File "co/main.py", line 62, in pipeline
    base_data_dict = await self.base_data_retriever()
  File "/home/nvidia/mydisk/gzh/projects/cosense/co/baseDataRetriever.py", line 51, in __call__
    data_dict[CONFIG['id']] = await self.get_ego_data()
  File "/home/nvidia/mydisk/gzh/projects/cosense/co/baseDataRetriever.py", line 14, in get_ego_data
    "lidar_np": await agent_server.wait_ego_pcd(),
  File "/home/nvidia/mydisk/gzh/projects/cosense/co/server.py", line 150, in wait_ego_pcd
    await self.ego_pcd.wait()
  File "/home/nvidia/mydisk/gzh/projects/cosense/co/utils.py", line 37, in wait
    await self._wait_condition(timeout)
  File "/home/nvidia/mydisk/gzh/projects/cosense/co/utils.py", line 64, in _wait_condition
    await self._condition.wait_for(lambda: self._value is not None)
  File "/home/nvidia/mydisk/miniconda3/envs/rospy/lib/python3.8/asyncio/locks.py", line 400, in wait_for
    await self.wait()
  File "/home/nvidia/mydisk/miniconda3/envs/rospy/lib/python3.8/asyncio/locks.py", line 373, in wait
    await fut
RuntimeError: Task <Task pending name='Task-18' coro=<CollaborationSystem.pipeline() running at co/main.py:62>> got Future <Future pending> attached to a different loop
2025-03-16 01:33:03,318 - asyncio - ERROR - Task exception was never retrieved
future: <Task finished name='Task-19' coro=<CollaborationSystem.pipeline() done, defined at co/main.py:61> exception=RuntimeError("Task <Task pending name='Task-19' coro=<CollaborationSystem.pipeline() running at co/main.py:62>> got Future <Future pending> attached to a different loop")>
Traceback (most recent call last):
  File "co/main.py", line 62, in pipeline
    base_data_dict = await self.base_data_retriever()
  File "/home/nvidia/mydisk/gzh/projects/cosense/co/baseDataRetriever.py", line 51, in __call__
    data_dict[CONFIG['id']] = await self.get_ego_data()
  File "/home/nvidia/mydisk/gzh/projects/cosense/co/baseDataRetriever.py", line 14, in get_ego_data
    "lidar_np": await agent_server.wait_ego_pcd(),
  File "/home/nvidia/mydisk/gzh/projects/cosense/co/server.py", line 150, in wait_ego_pcd
    await self.ego_pcd.wait()
  File "/home/nvidia/mydisk/gzh/projects/cosense/co/utils.py", line 37, in wait
    await self._wait_condition(timeout)
  File "/home/nvidia/mydisk/gzh/projects/cosense/co/utils.py", line 64, in _wait_condition
    await self._condition.wait_for(lambda: self._value is not None)
  File "/home/nvidia/mydisk/miniconda3/envs/rospy/lib/python3.8/asyncio/locks.py", line 400, in wait_for
    await self.wait()
  File "/home/nvidia/mydisk/miniconda3/envs/rospy/lib/python3.8/asyncio/locks.py", line 373, in wait
    await fut
RuntimeError: Task <Task pending name='Task-19' coro=<CollaborationSystem.pipeline() running at co/main.py:62>> got Future <Future pending> attached to a different loop
2025-03-16 01:33:04,320 - asyncio - ERROR - Task exception was never retrieved
future: <Task finished name='Task-20' coro=<CollaborationSystem.pipeline() done, defined at co/main.py:61> exception=RuntimeError("Task <Task pending name='Task-20' coro=<CollaborationSystem.pipeline() running at co/main.py:62>> got Future <Future pending> attached to a different loop")>
Traceback (most recent call last):
  File "co/main.py", line 62, in pipeline
    base_data_dict = await self.base_data_retriever()
  File "/home/nvidia/mydisk/gzh/projects/cosense/co/baseDataRetriever.py", line 51, in __call__
    data_dict[CONFIG['id']] = await self.get_ego_data()
  File "/home/nvidia/mydisk/gzh/projects/cosense/co/baseDataRetriever.py", line 14, in get_ego_data
    "lidar_np": await agent_server.wait_ego_pcd(),
  File "/home/nvidia/mydisk/gzh/projects/cosense/co/server.py", line 150, in wait_ego_pcd
    await self.ego_pcd.wait()
  File "/home/nvidia/mydisk/gzh/projects/cosense/co/utils.py", line 37, in wait
    await self._wait_condition(timeout)
  File "/home/nvidia/mydisk/gzh/projects/cosense/co/utils.py", line 64, in _wait_condition
    await self._condition.wait_for(lambda: self._value is not None)
  File "/home/nvidia/mydisk/miniconda3/envs/rospy/lib/python3.8/asyncio/locks.py", line 400, in wait_for
    await self.wait()
  File "/home/nvidia/mydisk/miniconda3/envs/rospy/lib/python3.8/asyncio/locks.py", line 373, in wait
    await fut
RuntimeError: Task <Task pending name='Task-20' coro=<CollaborationSystem.pipeline() running at co/main.py:62>> got Future <Future pending> attached to a different loop
2025-03-16 01:33:05,321 - asyncio - ERROR - Task exception was never retrieved
future: <Task finished name='Task-21' coro=<CollaborationSystem.pipeline() done, defined at co/main.py:61> exception=RuntimeError("Task <Task pending name='Task-21' coro=<CollaborationSystem.pipeline() running at co/main.py:62>> got Future <Future pending> attached to a different loop")>
Traceback (most recent call last):
  File "co/main.py", line 62, in pipeline
    base_data_dict = await self.base_data_retriever()
  File "/home/nvidia/mydisk/gzh/projects/cosense/co/baseDataRetriever.py", line 51, in __call__
    data_dict[CONFIG['id']] = await self.get_ego_data()
  File "/home/nvidia/mydisk/gzh/projects/cosense/co/baseDataRetriever.py", line 14, in get_ego_data
    "lidar_np": await agent_server.wait_ego_pcd(),
  File "/home/nvidia/mydisk/gzh/projects/cosense/co/server.py", line 150, in wait_ego_pcd
    await self.ego_pcd.wait()
  File "/home/nvidia/mydisk/gzh/projects/cosense/co/utils.py", line 37, in wait
    await self._wait_condition(timeout)
  File "/home/nvidia/mydisk/gzh/projects/cosense/co/utils.py", line 64, in _wait_condition
    await self._condition.wait_for(lambda: self._value is not None)
  File "/home/nvidia/mydisk/miniconda3/envs/rospy/lib/python3.8/asyncio/locks.py", line 400, in wait_for
    await self.wait()
  File "/home/nvidia/mydisk/miniconda3/envs/rospy/lib/python3.8/asyncio/locks.py", line 373, in wait
    await fut
RuntimeError: Task <Task pending name='Task-21' coro=<CollaborationSystem.pipeline() running at co/main.py:62>> got Future <Future pending> attached to a different loop
2025-03-16 01:33:06,323 - asyncio - ERROR - Task exception was never retrieved
future: <Task finished name='Task-22' coro=<CollaborationSystem.pipeline() done, defined at co/main.py:61> exception=RuntimeError("Task <Task pending name='Task-22' coro=<CollaborationSystem.pipeline() running at co/main.py:62>> got Future <Future pending> attached to a different loop")>
Traceback (most recent call last):
  File "co/main.py", line 62, in pipeline
    base_data_dict = await self.base_data_retriever()
  File "/home/nvidia/mydisk/gzh/projects/cosense/co/baseDataRetriever.py", line 51, in __call__
    data_dict[CONFIG['id']] = await self.get_ego_data()
  File "/home/nvidia/mydisk/gzh/projects/cosense/co/baseDataRetriever.py", line 14, in get_ego_data
    "lidar_np": await agent_server.wait_ego_pcd(),
  File "/home/nvidia/mydisk/gzh/projects/cosense/co/server.py", line 150, in wait_ego_pcd
    await self.ego_pcd.wait()
  File "/home/nvidia/mydisk/gzh/projects/cosense/co/utils.py", line 37, in wait
    await self._wait_condition(timeout)
  File "/home/nvidia/mydisk/gzh/projects/cosense/co/utils.py", line 64, in _wait_condition
    await self._condition.wait_for(lambda: self._value is not None)
  File "/home/nvidia/mydisk/miniconda3/envs/rospy/lib/python3.8/asyncio/locks.py", line 400, in wait_for
    await self.wait()
  File "/home/nvidia/mydisk/miniconda3/envs/rospy/lib/python3.8/asyncio/locks.py", line 373, in wait
    await fut
RuntimeError: Task <Task pending name='Task-22' coro=<CollaborationSystem.pipeline() running at co/main.py:62>> got Future <Future pending> attached to a different loop
2025-03-16 01:33:07,324 - asyncio - ERROR - Task exception was never retrieved
future: <Task finished name='Task-23' coro=<CollaborationSystem.pipeline() done, defined at co/main.py:61> exception=RuntimeError("Task <Task pending name='Task-23' coro=<CollaborationSystem.pipeline() running at co/main.py:62>> got Future <Future pending> attached to a different loop")>
Traceback (most recent call last):
  File "co/main.py", line 62, in pipeline
    base_data_dict = await self.base_data_retriever()
  File "/home/nvidia/mydisk/gzh/projects/cosense/co/baseDataRetriever.py", line 51, in __call__
    data_dict[CONFIG['id']] = await self.get_ego_data()
  File "/home/nvidia/mydisk/gzh/projects/cosense/co/baseDataRetriever.py", line 14, in get_ego_data
    "lidar_np": await agent_server.wait_ego_pcd(),
  File "/home/nvidia/mydisk/gzh/projects/cosense/co/server.py", line 150, in wait_ego_pcd
    await self.ego_pcd.wait()
  File "/home/nvidia/mydisk/gzh/projects/cosense/co/utils.py", line 37, in wait
    await self._wait_condition(timeout)
  File "/home/nvidia/mydisk/gzh/projects/cosense/co/utils.py", line 64, in _wait_condition
    await self._condition.wait_for(lambda: self._value is not None)
  File "/home/nvidia/mydisk/miniconda3/envs/rospy/lib/python3.8/asyncio/locks.py", line 400, in wait_for
    await self.wait()
  File "/home/nvidia/mydisk/miniconda3/envs/rospy/lib/python3.8/asyncio/locks.py", line 373, in wait
    await fut
RuntimeError: Task <Task pending name='Task-23' coro=<CollaborationSystem.pipeline() running at co/main.py:62>> got Future <Future pending> attached to a different loop
2025-03-16 01:33:08,326 - asyncio - ERROR - Task exception was never retrieved
future: <Task finished name='Task-24' coro=<CollaborationSystem.pipeline() done, defined at co/main.py:61> exception=RuntimeError("Task <Task pending name='Task-24' coro=<CollaborationSystem.pipeline() running at co/main.py:62>> got Future <Future pending> attached to a different loop")>
Traceback (most recent call last):
  File "co/main.py", line 62, in pipeline
    base_data_dict = await self.base_data_retriever()
  File "/home/nvidia/mydisk/gzh/projects/cosense/co/baseDataRetriever.py", line 51, in __call__
    data_dict[CONFIG['id']] = await self.get_ego_data()
  File "/home/nvidia/mydisk/gzh/projects/cosense/co/baseDataRetriever.py", line 14, in get_ego_data
    "lidar_np": await agent_server.wait_ego_pcd(),
  File "/home/nvidia/mydisk/gzh/projects/cosense/co/server.py", line 150, in wait_ego_pcd
    await self.ego_pcd.wait()
  File "/home/nvidia/mydisk/gzh/projects/cosense/co/utils.py", line 37, in wait
    await self._wait_condition(timeout)
  File "/home/nvidia/mydisk/gzh/projects/cosense/co/utils.py", line 64, in _wait_condition
    await self._condition.wait_for(lambda: self._value is not None)
  File "/home/nvidia/mydisk/miniconda3/envs/rospy/lib/python3.8/asyncio/locks.py", line 400, in wait_for
    await self.wait()
  File "/home/nvidia/mydisk/miniconda3/envs/rospy/lib/python3.8/asyncio/locks.py", line 373, in wait
    await fut
RuntimeError: Task <Task pending name='Task-24' coro=<CollaborationSystem.pipeline() running at co/main.py:62>> got Future <Future pending> attached to a different loop
2025-03-16 01:33:09,328 - asyncio - ERROR - Task exception was never retrieved
future: <Task finished name='Task-25' coro=<CollaborationSystem.pipeline() done, defined at co/main.py:61> exception=RuntimeError("Task <Task pending name='Task-25' coro=<CollaborationSystem.pipeline() running at co/main.py:62>> got Future <Future pending> attached to a different loop")>
Traceback (most recent call last):
  File "co/main.py", line 62, in pipeline
    base_data_dict = await self.base_data_retriever()
  File "/home/nvidia/mydisk/gzh/projects/cosense/co/baseDataRetriever.py", line 51, in __call__
    data_dict[CONFIG['id']] = await self.get_ego_data()
  File "/home/nvidia/mydisk/gzh/projects/cosense/co/baseDataRetriever.py", line 14, in get_ego_data
    "lidar_np": await agent_server.wait_ego_pcd(),
  File "/home/nvidia/mydisk/gzh/projects/cosense/co/server.py", line 150, in wait_ego_pcd
    await self.ego_pcd.wait()
  File "/home/nvidia/mydisk/gzh/projects/cosense/co/utils.py", line 37, in wait
    await self._wait_condition(timeout)
  File "/home/nvidia/mydisk/gzh/projects/cosense/co/utils.py", line 64, in _wait_condition
    await self._condition.wait_for(lambda: self._value is not None)
  File "/home/nvidia/mydisk/miniconda3/envs/rospy/lib/python3.8/asyncio/locks.py", line 400, in wait_for
    await self.wait()
  File "/home/nvidia/mydisk/miniconda3/envs/rospy/lib/python3.8/asyncio/locks.py", line 373, in wait
    await fut
RuntimeError: Task <Task pending name='Task-25' coro=<CollaborationSystem.pipeline() running at co/main.py:62>> got Future <Future pending> attached to a different loop
2025-03-16 01:33:10,330 - asyncio - ERROR - Task exception was never retrieved
future: <Task finished name='Task-26' coro=<CollaborationSystem.pipeline() done, defined at co/main.py:61> exception=RuntimeError("Task <Task pending name='Task-26' coro=<CollaborationSystem.pipeline() running at co/main.py:62>> got Future <Future pending> attached to a different loop")>
Traceback (most recent call last):
  File "co/main.py", line 62, in pipeline
    base_data_dict = await self.base_data_retriever()
  File "/home/nvidia/mydisk/gzh/projects/cosense/co/baseDataRetriever.py", line 51, in __call__
    data_dict[CONFIG['id']] = await self.get_ego_data()
  File "/home/nvidia/mydisk/gzh/projects/cosense/co/baseDataRetriever.py", line 14, in get_ego_data
    "lidar_np": await agent_server.wait_ego_pcd(),
  File "/home/nvidia/mydisk/gzh/projects/cosense/co/server.py", line 150, in wait_ego_pcd
    await self.ego_pcd.wait()
  File "/home/nvidia/mydisk/gzh/projects/cosense/co/utils.py", line 37, in wait
    await self._wait_condition(timeout)
  File "/home/nvidia/mydisk/gzh/projects/cosense/co/utils.py", line 64, in _wait_condition
    await self._condition.wait_for(lambda: self._value is not None)
  File "/home/nvidia/mydisk/miniconda3/envs/rospy/lib/python3.8/asyncio/locks.py", line 400, in wait_for
    await self.wait()
  File "/home/nvidia/mydisk/miniconda3/envs/rospy/lib/python3.8/asyncio/locks.py", line 373, in wait
    await fut
RuntimeError: Task <Task pending name='Task-26' coro=<CollaborationSystem.pipeline() running at co/main.py:62>> got Future <Future pending> attached to a different loop
2025-03-16 01:33:11,330 - asyncio - ERROR - Task exception was never retrieved
future: <Task finished name='Task-27' coro=<CollaborationSystem.pipeline() done, defined at co/main.py:61> exception=RuntimeError("Task <Task pending name='Task-27' coro=<CollaborationSystem.pipeline() running at co/main.py:62>> got Future <Future pending> attached to a different loop")>
Traceback (most recent call last):
  File "co/main.py", line 62, in pipeline
    base_data_dict = await self.base_data_retriever()
  File "/home/nvidia/mydisk/gzh/projects/cosense/co/baseDataRetriever.py", line 51, in __call__
    data_dict[CONFIG['id']] = await self.get_ego_data()
  File "/home/nvidia/mydisk/gzh/projects/cosense/co/baseDataRetriever.py", line 14, in get_ego_data
    "lidar_np": await agent_server.wait_ego_pcd(),
  File "/home/nvidia/mydisk/gzh/projects/cosense/co/server.py", line 150, in wait_ego_pcd
    await self.ego_pcd.wait()
  File "/home/nvidia/mydisk/gzh/projects/cosense/co/utils.py", line 37, in wait
    await self._wait_condition(timeout)
  File "/home/nvidia/mydisk/gzh/projects/cosense/co/utils.py", line 64, in _wait_condition
    await self._condition.wait_for(lambda: self._value is not None)
  File "/home/nvidia/mydisk/miniconda3/envs/rospy/lib/python3.8/asyncio/locks.py", line 400, in wait_for
    await self.wait()
  File "/home/nvidia/mydisk/miniconda3/envs/rospy/lib/python3.8/asyncio/locks.py", line 373, in wait
    await fut
RuntimeError: Task <Task pending name='Task-27' coro=<CollaborationSystem.pipeline() running at co/main.py:62>> got Future <Future pending> attached to a different loop
2025-03-16 01:33:12,332 - asyncio - ERROR - Task exception was never retrieved
future: <Task finished name='Task-28' coro=<CollaborationSystem.pipeline() done, defined at co/main.py:61> exception=RuntimeError("Task <Task pending name='Task-28' coro=<CollaborationSystem.pipeline() running at co/main.py:62>> got Future <Future pending> attached to a different loop")>
Traceback (most recent call last):
  File "co/main.py", line 62, in pipeline
    base_data_dict = await self.base_data_retriever()
  File "/home/nvidia/mydisk/gzh/projects/cosense/co/baseDataRetriever.py", line 51, in __call__
    data_dict[CONFIG['id']] = await self.get_ego_data()
  File "/home/nvidia/mydisk/gzh/projects/cosense/co/baseDataRetriever.py", line 14, in get_ego_data
    "lidar_np": await agent_server.wait_ego_pcd(),
  File "/home/nvidia/mydisk/gzh/projects/cosense/co/server.py", line 150, in wait_ego_pcd
    await self.ego_pcd.wait()
  File "/home/nvidia/mydisk/gzh/projects/cosense/co/utils.py", line 37, in wait
    await self._wait_condition(timeout)
  File "/home/nvidia/mydisk/gzh/projects/cosense/co/utils.py", line 64, in _wait_condition
    await self._condition.wait_for(lambda: self._value is not None)
  File "/home/nvidia/mydisk/miniconda3/envs/rospy/lib/python3.8/asyncio/locks.py", line 400, in wait_for
    await self.wait()
  File "/home/nvidia/mydisk/miniconda3/envs/rospy/lib/python3.8/asyncio/locks.py", line 373, in wait
    await fut
RuntimeError: Task <Task pending name='Task-28' coro=<CollaborationSystem.pipeline() running at co/main.py:62>> got Future <Future pending> attached to a different loop
2025-03-16 01:33:13,333 - asyncio - ERROR - Task exception was never retrieved
future: <Task finished name='Task-29' coro=<CollaborationSystem.pipeline() done, defined at co/main.py:61> exception=RuntimeError("Task <Task pending name='Task-29' coro=<CollaborationSystem.pipeline() running at co/main.py:62>> got Future <Future pending> attached to a different loop")>
Traceback (most recent call last):
  File "co/main.py", line 62, in pipeline
    base_data_dict = await self.base_data_retriever()
  File "/home/nvidia/mydisk/gzh/projects/cosense/co/baseDataRetriever.py", line 51, in __call__
    data_dict[CONFIG['id']] = await self.get_ego_data()
  File "/home/nvidia/mydisk/gzh/projects/cosense/co/baseDataRetriever.py", line 14, in get_ego_data
    "lidar_np": await agent_server.wait_ego_pcd(),
  File "/home/nvidia/mydisk/gzh/projects/cosense/co/server.py", line 150, in wait_ego_pcd
    await self.ego_pcd.wait()
  File "/home/nvidia/mydisk/gzh/projects/cosense/co/utils.py", line 37, in wait
    await self._wait_condition(timeout)
  File "/home/nvidia/mydisk/gzh/projects/cosense/co/utils.py", line 64, in _wait_condition
    await self._condition.wait_for(lambda: self._value is not None)
  File "/home/nvidia/mydisk/miniconda3/envs/rospy/lib/python3.8/asyncio/locks.py", line 400, in wait_for
    await self.wait()
  File "/home/nvidia/mydisk/miniconda3/envs/rospy/lib/python3.8/asyncio/locks.py", line 373, in wait
    await fut
RuntimeError: Task <Task pending name='Task-29' coro=<CollaborationSystem.pipeline() running at co/main.py:62>> got Future <Future pending> attached to a different loop
2025-03-16 01:33:13,455 - root - INFO - 用户主动终止程序
2025-03-16 01:33:13,455 - root - INFO - ==== 系统关闭 ====
2025-03-16 01:33:13,456 - rospy.core - INFO - signal_shutdown [atexit]
