2025-03-16 01:32:50,218 - Config - INFO - 当前配置：{
  "id": 12345678,
  "mode": "CO",
  "keepalive_timeout": 1,
  "zmq": {
    "in_port": 13415,
    "out_port": 13416,
    "max_cache": 1000
  },
  "ros": {
    "pointcloud_topic": "pcd_topic0",
    "queue_size": 10
  },
  "processing": {
    "interval": 1,
    "max_workers": 4,
    "overlap_threshold": 0.3,
    "H": 100,
    "W": 100
  }
}
2025-03-16 01:32:50,219 - asyncio - DEBUG - Using selector: EpollSelector
2025-03-16 01:32:50,221 - rosout - DEBUG - signal handlers for rospy disabled
2025-03-16 01:32:50,367 - ZMQ - INFO - ZMQ接收循环启动
2025-03-16 01:32:50,368 - ROS - INFO - 启动ROS线程
2025-03-16 01:32:50,369 - asyncio - ERROR - Task exception was never retrieved
future: <Task finished name='Task-6' coro=<CollaborationSystem.pipeline() done, defined at co/main.py:61> exception=RuntimeError("Task <Task pending name='Task-6' coro=<CollaborationSystem.pipeline() running at co/main.py:62>> got Future <Future pending> attached to a different loop")>
Traceback (most recent call last):
  File "co/main.py", line 62, in pipeline
    base_data_dict = await self.base_data_retriever()
  File "/home/nvidia/mydisk/gzh/projects/cosense/co/baseDataRetriever.py", line 51, in __call__
    data_dict[CONFIG['id']] = await self.get_ego_data()
  File "/home/nvidia/mydisk/gzh/projects/cosense/co/baseDataRetriever.py", line 14, in get_ego_data
    "lidar_np": await agent_server.wait_ego_pcd(),
  File "/home/nvidia/mydisk/gzh/projects/cosense/co/server.py", line 150, in wait_ego_pcd
    await self.ego_pcd.wait()
  File "/home/nvidia/mydisk/gzh/projects/cosense/co/utils.py", line 37, in wait
    await self._wait_condition(timeout)
  File "/home/nvidia/mydisk/gzh/projects/cosense/co/utils.py", line 64, in _wait_condition
    await self._condition.wait_for(lambda: self._value is not None)
  File "/home/nvidia/mydisk/miniconda3/envs/rospy/lib/python3.8/asyncio/locks.py", line 400, in wait_for
    await self.wait()
  File "/home/nvidia/mydisk/miniconda3/envs/rospy/lib/python3.8/asyncio/locks.py", line 373, in wait
    await fut
RuntimeError: Task <Task pending name='Task-6' coro=<CollaborationSystem.pipeline() running at co/main.py:62>> got Future <Future pending> attached to a different loop
2025-03-16 01:32:50,371 - rospy.topics - DEBUG - tm._add: /pcd_topic0, sensor_msgs/PointCloud2, sub
2025-03-16 01:32:50,372 - rospy.registration - DEBUG - master.registerSubscriber(/async_ros_node, /pcd_topic0, sensor_msgs/PointCloud2, http://miivii-tegra:36673/)
2025-03-16 01:32:50,375 - rospy.impl.masterslave - DEBUG - connect[/pcd_topic0]: calling requestTopic(/async_ros_node, /pcd_topic0, [['TCPROS']])
2025-03-16 01:32:50,375 - rospy.impl.masterslave - DEBUG - connect[/pcd_topic0]: calling requestTopic(/async_ros_node, /pcd_topic0, [['TCPROS']])
2025-03-16 01:32:50,375 - rospy.impl.masterslave - DEBUG - connect[/pcd_topic0]: calling requestTopic(/async_ros_node, /pcd_topic0, [['TCPROS']])
2025-03-16 01:32:50,376 - rospy.impl.masterslave - DEBUG - connect[/pcd_topic0]: calling requestTopic(/async_ros_node, /pcd_topic0, [['TCPROS']])
2025-03-16 01:32:50,380 - rospy.impl.masterslave - DEBUG - connect[http://miivii-tegra:37381/]: requestTopic did not succeed -111, [Errno 111] Connection refused
2025-03-16 01:32:50,380 - rospy.impl.masterslave - DEBUG - connect[/pcd_topic0]: requestTopic returned protocol list ['TCPROS', 'miivii-tegra', 37041]
2025-03-16 01:32:50,381 - rospy.impl.masterslave - DEBUG - connect[http://miivii-tegra:35691/]: requestTopic did not succeed -111, [Errno 111] Connection refused
2025-03-16 01:32:50,381 - rospy.internal - INFO - topic[/pcd_topic0] adding connection to [http://miivii-tegra:39725/], count 0
2025-03-16 01:32:50,381 - rospy.impl.masterslave - DEBUG - connect[http://miivii-tegra:45155/]: requestTopic did not succeed -111, [Errno 111] Connection refused
2025-03-16 01:32:50,384 - rospy.tcpros - DEBUG - [/pcd_topic0]: writing header
2025-03-16 01:32:50,384 - rospy.tcpros - DEBUG - receive_loop for [/pcd_topic0]
2025-03-16 01:32:50,407 - rospy.impl.masterslave - DEBUG - requestTopic('/rosout', '/rosout', [['TCPROS']])
2025-03-16 01:32:50,407 - rospy.impl.masterslave - DEBUG - requestTopic[/rosout]: choosing protocol TCPROS
2025-03-16 01:32:50,407 - rospy.impl.masterslave - DEBUG - requestTopic('/rosout', '/rosout', [['TCPROS']]) returns (1, 'ready on miivii-tegra:33465', ['TCPROS', 'miivii-tegra', 33465])
2025-03-16 01:32:50,513 - rospy.tcpros - DEBUG - [/rosout]: writing header
2025-03-16 01:32:50,515 - rospy.internal - INFO - topic[/rosout] adding connection to [/rosout], count 0
2025-03-16 01:32:51,203 - ROS - INFO - 收到点云数据: 100 个点
2025-03-16 01:32:51,371 - asyncio - ERROR - Task exception was never retrieved
future: <Task finished name='Task-8' coro=<CollaborationSystem.pipeline() done, defined at co/main.py:61> exception=RuntimeError("Task <Task pending name='Task-8' coro=<CollaborationSystem.pipeline() running at co/main.py:62>> got Future <Future pending> attached to a different loop")>
Traceback (most recent call last):
  File "co/main.py", line 62, in pipeline
    base_data_dict = await self.base_data_retriever()
  File "/home/nvidia/mydisk/gzh/projects/cosense/co/baseDataRetriever.py", line 51, in __call__
    data_dict[CONFIG['id']] = await self.get_ego_data()
  File "/home/nvidia/mydisk/gzh/projects/cosense/co/baseDataRetriever.py", line 14, in get_ego_data
    "lidar_np": await agent_server.wait_ego_pcd(),
  File "/home/nvidia/mydisk/gzh/projects/cosense/co/server.py", line 150, in wait_ego_pcd
    await self.ego_pcd.wait()
  File "/home/nvidia/mydisk/gzh/projects/cosense/co/utils.py", line 37, in wait
    await self._wait_condition(timeout)
  File "/home/nvidia/mydisk/gzh/projects/cosense/co/utils.py", line 64, in _wait_condition
    await self._condition.wait_for(lambda: self._value is not None)
  File "/home/nvidia/mydisk/miniconda3/envs/rospy/lib/python3.8/asyncio/locks.py", line 400, in wait_for
    await self.wait()
  File "/home/nvidia/mydisk/miniconda3/envs/rospy/lib/python3.8/asyncio/locks.py", line 373, in wait
    await fut
RuntimeError: Task <Task pending name='Task-8' coro=<CollaborationSystem.pipeline() running at co/main.py:62>> got Future <Future pending> attached to a different loop
2025-03-16 01:32:52,202 - ROS - INFO - 收到点云数据: 100 个点
2025-03-16 01:32:52,372 - asyncio - ERROR - Task exception was never retrieved
future: <Task finished name='Task-10' coro=<CollaborationSystem.pipeline() done, defined at co/main.py:61> exception=RuntimeError("Task <Task pending name='Task-10' coro=<CollaborationSystem.pipeline() running at co/main.py:62>> got Future <Future pending> attached to a different loop")>
Traceback (most recent call last):
  File "co/main.py", line 62, in pipeline
    base_data_dict = await self.base_data_retriever()
  File "/home/nvidia/mydisk/gzh/projects/cosense/co/baseDataRetriever.py", line 51, in __call__
    data_dict[CONFIG['id']] = await self.get_ego_data()
  File "/home/nvidia/mydisk/gzh/projects/cosense/co/baseDataRetriever.py", line 14, in get_ego_data
    "lidar_np": await agent_server.wait_ego_pcd(),
  File "/home/nvidia/mydisk/gzh/projects/cosense/co/server.py", line 150, in wait_ego_pcd
    await self.ego_pcd.wait()
  File "/home/nvidia/mydisk/gzh/projects/cosense/co/utils.py", line 37, in wait
    await self._wait_condition(timeout)
  File "/home/nvidia/mydisk/gzh/projects/cosense/co/utils.py", line 64, in _wait_condition
    await self._condition.wait_for(lambda: self._value is not None)
  File "/home/nvidia/mydisk/miniconda3/envs/rospy/lib/python3.8/asyncio/locks.py", line 400, in wait_for
    await self.wait()
  File "/home/nvidia/mydisk/miniconda3/envs/rospy/lib/python3.8/asyncio/locks.py", line 373, in wait
    await fut
RuntimeError: Task <Task pending name='Task-10' coro=<CollaborationSystem.pipeline() running at co/main.py:62>> got Future <Future pending> attached to a different loop
2025-03-16 01:32:53,202 - ROS - INFO - 收到点云数据: 100 个点
2025-03-16 01:32:53,375 - asyncio - ERROR - Task exception was never retrieved
future: <Task finished name='Task-12' coro=<CollaborationSystem.pipeline() done, defined at co/main.py:61> exception=RuntimeError("Task <Task pending name='Task-12' coro=<CollaborationSystem.pipeline() running at co/main.py:62>> got Future <Future pending> attached to a different loop")>
Traceback (most recent call last):
  File "co/main.py", line 62, in pipeline
    base_data_dict = await self.base_data_retriever()
  File "/home/nvidia/mydisk/gzh/projects/cosense/co/baseDataRetriever.py", line 51, in __call__
    data_dict[CONFIG['id']] = await self.get_ego_data()
  File "/home/nvidia/mydisk/gzh/projects/cosense/co/baseDataRetriever.py", line 14, in get_ego_data
    "lidar_np": await agent_server.wait_ego_pcd(),
  File "/home/nvidia/mydisk/gzh/projects/cosense/co/server.py", line 150, in wait_ego_pcd
    await self.ego_pcd.wait()
  File "/home/nvidia/mydisk/gzh/projects/cosense/co/utils.py", line 37, in wait
    await self._wait_condition(timeout)
  File "/home/nvidia/mydisk/gzh/projects/cosense/co/utils.py", line 64, in _wait_condition
    await self._condition.wait_for(lambda: self._value is not None)
  File "/home/nvidia/mydisk/miniconda3/envs/rospy/lib/python3.8/asyncio/locks.py", line 400, in wait_for
    await self.wait()
  File "/home/nvidia/mydisk/miniconda3/envs/rospy/lib/python3.8/asyncio/locks.py", line 373, in wait
    await fut
RuntimeError: Task <Task pending name='Task-12' coro=<CollaborationSystem.pipeline() running at co/main.py:62>> got Future <Future pending> attached to a different loop
2025-03-16 01:32:54,203 - ROS - INFO - 收到点云数据: 100 个点
2025-03-16 01:32:54,377 - asyncio - ERROR - Task exception was never retrieved
future: <Task finished name='Task-14' coro=<CollaborationSystem.pipeline() done, defined at co/main.py:61> exception=RuntimeError("Task <Task pending name='Task-14' coro=<CollaborationSystem.pipeline() running at co/main.py:62>> got Future <Future pending> attached to a different loop")>
Traceback (most recent call last):
  File "co/main.py", line 62, in pipeline
    base_data_dict = await self.base_data_retriever()
  File "/home/nvidia/mydisk/gzh/projects/cosense/co/baseDataRetriever.py", line 51, in __call__
    data_dict[CONFIG['id']] = await self.get_ego_data()
  File "/home/nvidia/mydisk/gzh/projects/cosense/co/baseDataRetriever.py", line 14, in get_ego_data
    "lidar_np": await agent_server.wait_ego_pcd(),
  File "/home/nvidia/mydisk/gzh/projects/cosense/co/server.py", line 150, in wait_ego_pcd
    await self.ego_pcd.wait()
  File "/home/nvidia/mydisk/gzh/projects/cosense/co/utils.py", line 37, in wait
    await self._wait_condition(timeout)
  File "/home/nvidia/mydisk/gzh/projects/cosense/co/utils.py", line 64, in _wait_condition
    await self._condition.wait_for(lambda: self._value is not None)
  File "/home/nvidia/mydisk/miniconda3/envs/rospy/lib/python3.8/asyncio/locks.py", line 400, in wait_for
    await self.wait()
  File "/home/nvidia/mydisk/miniconda3/envs/rospy/lib/python3.8/asyncio/locks.py", line 373, in wait
    await fut
RuntimeError: Task <Task pending name='Task-14' coro=<CollaborationSystem.pipeline() running at co/main.py:62>> got Future <Future pending> attached to a different loop
2025-03-16 01:32:55,204 - ROS - INFO - 收到点云数据: 100 个点
2025-03-16 01:32:55,379 - asyncio - ERROR - Task exception was never retrieved
future: <Task finished name='Task-16' coro=<CollaborationSystem.pipeline() done, defined at co/main.py:61> exception=RuntimeError("Task <Task pending name='Task-16' coro=<CollaborationSystem.pipeline() running at co/main.py:62>> got Future <Future pending> attached to a different loop")>
Traceback (most recent call last):
  File "co/main.py", line 62, in pipeline
    base_data_dict = await self.base_data_retriever()
  File "/home/nvidia/mydisk/gzh/projects/cosense/co/baseDataRetriever.py", line 51, in __call__
    data_dict[CONFIG['id']] = await self.get_ego_data()
  File "/home/nvidia/mydisk/gzh/projects/cosense/co/baseDataRetriever.py", line 14, in get_ego_data
    "lidar_np": await agent_server.wait_ego_pcd(),
  File "/home/nvidia/mydisk/gzh/projects/cosense/co/server.py", line 150, in wait_ego_pcd
    await self.ego_pcd.wait()
  File "/home/nvidia/mydisk/gzh/projects/cosense/co/utils.py", line 37, in wait
    await self._wait_condition(timeout)
  File "/home/nvidia/mydisk/gzh/projects/cosense/co/utils.py", line 64, in _wait_condition
    await self._condition.wait_for(lambda: self._value is not None)
  File "/home/nvidia/mydisk/miniconda3/envs/rospy/lib/python3.8/asyncio/locks.py", line 400, in wait_for
    await self.wait()
  File "/home/nvidia/mydisk/miniconda3/envs/rospy/lib/python3.8/asyncio/locks.py", line 373, in wait
    await fut
RuntimeError: Task <Task pending name='Task-16' coro=<CollaborationSystem.pipeline() running at co/main.py:62>> got Future <Future pending> attached to a different loop
2025-03-16 01:32:56,203 - ROS - INFO - 收到点云数据: 100 个点
2025-03-16 01:32:56,380 - asyncio - ERROR - Task exception was never retrieved
future: <Task finished name='Task-18' coro=<CollaborationSystem.pipeline() done, defined at co/main.py:61> exception=RuntimeError("Task <Task pending name='Task-18' coro=<CollaborationSystem.pipeline() running at co/main.py:62>> got Future <Future pending> attached to a different loop")>
Traceback (most recent call last):
  File "co/main.py", line 62, in pipeline
    base_data_dict = await self.base_data_retriever()
  File "/home/nvidia/mydisk/gzh/projects/cosense/co/baseDataRetriever.py", line 51, in __call__
    data_dict[CONFIG['id']] = await self.get_ego_data()
  File "/home/nvidia/mydisk/gzh/projects/cosense/co/baseDataRetriever.py", line 14, in get_ego_data
    "lidar_np": await agent_server.wait_ego_pcd(),
  File "/home/nvidia/mydisk/gzh/projects/cosense/co/server.py", line 150, in wait_ego_pcd
    await self.ego_pcd.wait()
  File "/home/nvidia/mydisk/gzh/projects/cosense/co/utils.py", line 37, in wait
    await self._wait_condition(timeout)
  File "/home/nvidia/mydisk/gzh/projects/cosense/co/utils.py", line 64, in _wait_condition
    await self._condition.wait_for(lambda: self._value is not None)
  File "/home/nvidia/mydisk/miniconda3/envs/rospy/lib/python3.8/asyncio/locks.py", line 400, in wait_for
    await self.wait()
  File "/home/nvidia/mydisk/miniconda3/envs/rospy/lib/python3.8/asyncio/locks.py", line 373, in wait
    await fut
RuntimeError: Task <Task pending name='Task-18' coro=<CollaborationSystem.pipeline() running at co/main.py:62>> got Future <Future pending> attached to a different loop
2025-03-16 01:32:57,203 - ROS - INFO - 收到点云数据: 100 个点
2025-03-16 01:32:57,383 - asyncio - ERROR - Task exception was never retrieved
future: <Task finished name='Task-20' coro=<CollaborationSystem.pipeline() done, defined at co/main.py:61> exception=RuntimeError("Task <Task pending name='Task-20' coro=<CollaborationSystem.pipeline() running at co/main.py:62>> got Future <Future pending> attached to a different loop")>
Traceback (most recent call last):
  File "co/main.py", line 62, in pipeline
    base_data_dict = await self.base_data_retriever()
  File "/home/nvidia/mydisk/gzh/projects/cosense/co/baseDataRetriever.py", line 51, in __call__
    data_dict[CONFIG['id']] = await self.get_ego_data()
  File "/home/nvidia/mydisk/gzh/projects/cosense/co/baseDataRetriever.py", line 14, in get_ego_data
    "lidar_np": await agent_server.wait_ego_pcd(),
  File "/home/nvidia/mydisk/gzh/projects/cosense/co/server.py", line 150, in wait_ego_pcd
    await self.ego_pcd.wait()
  File "/home/nvidia/mydisk/gzh/projects/cosense/co/utils.py", line 37, in wait
    await self._wait_condition(timeout)
  File "/home/nvidia/mydisk/gzh/projects/cosense/co/utils.py", line 64, in _wait_condition
    await self._condition.wait_for(lambda: self._value is not None)
  File "/home/nvidia/mydisk/miniconda3/envs/rospy/lib/python3.8/asyncio/locks.py", line 400, in wait_for
    await self.wait()
  File "/home/nvidia/mydisk/miniconda3/envs/rospy/lib/python3.8/asyncio/locks.py", line 373, in wait
    await fut
RuntimeError: Task <Task pending name='Task-20' coro=<CollaborationSystem.pipeline() running at co/main.py:62>> got Future <Future pending> attached to a different loop
2025-03-16 01:32:58,203 - ROS - INFO - 收到点云数据: 100 个点
2025-03-16 01:32:58,385 - asyncio - ERROR - Task exception was never retrieved
future: <Task finished name='Task-22' coro=<CollaborationSystem.pipeline() done, defined at co/main.py:61> exception=RuntimeError("Task <Task pending name='Task-22' coro=<CollaborationSystem.pipeline() running at co/main.py:62>> got Future <Future pending> attached to a different loop")>
Traceback (most recent call last):
  File "co/main.py", line 62, in pipeline
    base_data_dict = await self.base_data_retriever()
  File "/home/nvidia/mydisk/gzh/projects/cosense/co/baseDataRetriever.py", line 51, in __call__
    data_dict[CONFIG['id']] = await self.get_ego_data()
  File "/home/nvidia/mydisk/gzh/projects/cosense/co/baseDataRetriever.py", line 14, in get_ego_data
    "lidar_np": await agent_server.wait_ego_pcd(),
  File "/home/nvidia/mydisk/gzh/projects/cosense/co/server.py", line 150, in wait_ego_pcd
    await self.ego_pcd.wait()
  File "/home/nvidia/mydisk/gzh/projects/cosense/co/utils.py", line 37, in wait
    await self._wait_condition(timeout)
  File "/home/nvidia/mydisk/gzh/projects/cosense/co/utils.py", line 64, in _wait_condition
    await self._condition.wait_for(lambda: self._value is not None)
  File "/home/nvidia/mydisk/miniconda3/envs/rospy/lib/python3.8/asyncio/locks.py", line 400, in wait_for
    await self.wait()
  File "/home/nvidia/mydisk/miniconda3/envs/rospy/lib/python3.8/asyncio/locks.py", line 373, in wait
    await fut
RuntimeError: Task <Task pending name='Task-22' coro=<CollaborationSystem.pipeline() running at co/main.py:62>> got Future <Future pending> attached to a different loop
2025-03-16 01:32:59,202 - ROS - INFO - 收到点云数据: 100 个点
2025-03-16 01:32:59,387 - asyncio - ERROR - Task exception was never retrieved
future: <Task finished name='Task-24' coro=<CollaborationSystem.pipeline() done, defined at co/main.py:61> exception=RuntimeError("Task <Task pending name='Task-24' coro=<CollaborationSystem.pipeline() running at co/main.py:62>> got Future <Future pending> attached to a different loop")>
Traceback (most recent call last):
  File "co/main.py", line 62, in pipeline
    base_data_dict = await self.base_data_retriever()
  File "/home/nvidia/mydisk/gzh/projects/cosense/co/baseDataRetriever.py", line 51, in __call__
    data_dict[CONFIG['id']] = await self.get_ego_data()
  File "/home/nvidia/mydisk/gzh/projects/cosense/co/baseDataRetriever.py", line 14, in get_ego_data
    "lidar_np": await agent_server.wait_ego_pcd(),
  File "/home/nvidia/mydisk/gzh/projects/cosense/co/server.py", line 150, in wait_ego_pcd
    await self.ego_pcd.wait()
  File "/home/nvidia/mydisk/gzh/projects/cosense/co/utils.py", line 37, in wait
    await self._wait_condition(timeout)
  File "/home/nvidia/mydisk/gzh/projects/cosense/co/utils.py", line 64, in _wait_condition
    await self._condition.wait_for(lambda: self._value is not None)
  File "/home/nvidia/mydisk/miniconda3/envs/rospy/lib/python3.8/asyncio/locks.py", line 400, in wait_for
    await self.wait()
  File "/home/nvidia/mydisk/miniconda3/envs/rospy/lib/python3.8/asyncio/locks.py", line 373, in wait
    await fut
RuntimeError: Task <Task pending name='Task-24' coro=<CollaborationSystem.pipeline() running at co/main.py:62>> got Future <Future pending> attached to a different loop
2025-03-16 01:33:00,202 - ROS - INFO - 收到点云数据: 100 个点
2025-03-16 01:33:00,389 - asyncio - ERROR - Task exception was never retrieved
future: <Task finished name='Task-26' coro=<CollaborationSystem.pipeline() done, defined at co/main.py:61> exception=RuntimeError("Task <Task pending name='Task-26' coro=<CollaborationSystem.pipeline() running at co/main.py:62>> got Future <Future pending> attached to a different loop")>
Traceback (most recent call last):
  File "co/main.py", line 62, in pipeline
    base_data_dict = await self.base_data_retriever()
  File "/home/nvidia/mydisk/gzh/projects/cosense/co/baseDataRetriever.py", line 51, in __call__
    data_dict[CONFIG['id']] = await self.get_ego_data()
  File "/home/nvidia/mydisk/gzh/projects/cosense/co/baseDataRetriever.py", line 14, in get_ego_data
    "lidar_np": await agent_server.wait_ego_pcd(),
  File "/home/nvidia/mydisk/gzh/projects/cosense/co/server.py", line 150, in wait_ego_pcd
    await self.ego_pcd.wait()
  File "/home/nvidia/mydisk/gzh/projects/cosense/co/utils.py", line 37, in wait
    await self._wait_condition(timeout)
  File "/home/nvidia/mydisk/gzh/projects/cosense/co/utils.py", line 64, in _wait_condition
    await self._condition.wait_for(lambda: self._value is not None)
  File "/home/nvidia/mydisk/miniconda3/envs/rospy/lib/python3.8/asyncio/locks.py", line 400, in wait_for
    await self.wait()
  File "/home/nvidia/mydisk/miniconda3/envs/rospy/lib/python3.8/asyncio/locks.py", line 373, in wait
    await fut
RuntimeError: Task <Task pending name='Task-26' coro=<CollaborationSystem.pipeline() running at co/main.py:62>> got Future <Future pending> attached to a different loop
2025-03-16 01:33:01,201 - ROS - INFO - 收到点云数据: 100 个点
2025-03-16 01:33:01,390 - asyncio - ERROR - Task exception was never retrieved
future: <Task finished name='Task-28' coro=<CollaborationSystem.pipeline() done, defined at co/main.py:61> exception=RuntimeError("Task <Task pending name='Task-28' coro=<CollaborationSystem.pipeline() running at co/main.py:62>> got Future <Future pending> attached to a different loop")>
Traceback (most recent call last):
  File "co/main.py", line 62, in pipeline
    base_data_dict = await self.base_data_retriever()
  File "/home/nvidia/mydisk/gzh/projects/cosense/co/baseDataRetriever.py", line 51, in __call__
    data_dict[CONFIG['id']] = await self.get_ego_data()
  File "/home/nvidia/mydisk/gzh/projects/cosense/co/baseDataRetriever.py", line 14, in get_ego_data
    "lidar_np": await agent_server.wait_ego_pcd(),
  File "/home/nvidia/mydisk/gzh/projects/cosense/co/server.py", line 150, in wait_ego_pcd
    await self.ego_pcd.wait()
  File "/home/nvidia/mydisk/gzh/projects/cosense/co/utils.py", line 37, in wait
    await self._wait_condition(timeout)
  File "/home/nvidia/mydisk/gzh/projects/cosense/co/utils.py", line 64, in _wait_condition
    await self._condition.wait_for(lambda: self._value is not None)
  File "/home/nvidia/mydisk/miniconda3/envs/rospy/lib/python3.8/asyncio/locks.py", line 400, in wait_for
    await self.wait()
  File "/home/nvidia/mydisk/miniconda3/envs/rospy/lib/python3.8/asyncio/locks.py", line 373, in wait
    await fut
RuntimeError: Task <Task pending name='Task-28' coro=<CollaborationSystem.pipeline() running at co/main.py:62>> got Future <Future pending> attached to a different loop
2025-03-16 01:33:02,203 - ROS - INFO - 收到点云数据: 100 个点
2025-03-16 01:33:02,392 - asyncio - ERROR - Task exception was never retrieved
future: <Task finished name='Task-30' coro=<CollaborationSystem.pipeline() done, defined at co/main.py:61> exception=RuntimeError("Task <Task pending name='Task-30' coro=<CollaborationSystem.pipeline() running at co/main.py:62>> got Future <Future pending> attached to a different loop")>
Traceback (most recent call last):
  File "co/main.py", line 62, in pipeline
    base_data_dict = await self.base_data_retriever()
  File "/home/nvidia/mydisk/gzh/projects/cosense/co/baseDataRetriever.py", line 51, in __call__
    data_dict[CONFIG['id']] = await self.get_ego_data()
  File "/home/nvidia/mydisk/gzh/projects/cosense/co/baseDataRetriever.py", line 14, in get_ego_data
    "lidar_np": await agent_server.wait_ego_pcd(),
  File "/home/nvidia/mydisk/gzh/projects/cosense/co/server.py", line 150, in wait_ego_pcd
    await self.ego_pcd.wait()
  File "/home/nvidia/mydisk/gzh/projects/cosense/co/utils.py", line 37, in wait
    await self._wait_condition(timeout)
  File "/home/nvidia/mydisk/gzh/projects/cosense/co/utils.py", line 64, in _wait_condition
    await self._condition.wait_for(lambda: self._value is not None)
  File "/home/nvidia/mydisk/miniconda3/envs/rospy/lib/python3.8/asyncio/locks.py", line 400, in wait_for
    await self.wait()
  File "/home/nvidia/mydisk/miniconda3/envs/rospy/lib/python3.8/asyncio/locks.py", line 373, in wait
    await fut
RuntimeError: Task <Task pending name='Task-30' coro=<CollaborationSystem.pipeline() running at co/main.py:62>> got Future <Future pending> attached to a different loop
2025-03-16 01:33:03,203 - ROS - INFO - 收到点云数据: 100 个点
2025-03-16 01:33:03,395 - asyncio - ERROR - Task exception was never retrieved
future: <Task finished name='Task-32' coro=<CollaborationSystem.pipeline() done, defined at co/main.py:61> exception=RuntimeError("Task <Task pending name='Task-32' coro=<CollaborationSystem.pipeline() running at co/main.py:62>> got Future <Future pending> attached to a different loop")>
Traceback (most recent call last):
  File "co/main.py", line 62, in pipeline
    base_data_dict = await self.base_data_retriever()
  File "/home/nvidia/mydisk/gzh/projects/cosense/co/baseDataRetriever.py", line 51, in __call__
    data_dict[CONFIG['id']] = await self.get_ego_data()
  File "/home/nvidia/mydisk/gzh/projects/cosense/co/baseDataRetriever.py", line 14, in get_ego_data
    "lidar_np": await agent_server.wait_ego_pcd(),
  File "/home/nvidia/mydisk/gzh/projects/cosense/co/server.py", line 150, in wait_ego_pcd
    await self.ego_pcd.wait()
  File "/home/nvidia/mydisk/gzh/projects/cosense/co/utils.py", line 37, in wait
    await self._wait_condition(timeout)
  File "/home/nvidia/mydisk/gzh/projects/cosense/co/utils.py", line 64, in _wait_condition
    await self._condition.wait_for(lambda: self._value is not None)
  File "/home/nvidia/mydisk/miniconda3/envs/rospy/lib/python3.8/asyncio/locks.py", line 400, in wait_for
    await self.wait()
  File "/home/nvidia/mydisk/miniconda3/envs/rospy/lib/python3.8/asyncio/locks.py", line 373, in wait
    await fut
RuntimeError: Task <Task pending name='Task-32' coro=<CollaborationSystem.pipeline() running at co/main.py:62>> got Future <Future pending> attached to a different loop
2025-03-16 01:33:04,202 - ROS - INFO - 收到点云数据: 100 个点
2025-03-16 01:33:04,397 - asyncio - ERROR - Task exception was never retrieved
future: <Task finished name='Task-34' coro=<CollaborationSystem.pipeline() done, defined at co/main.py:61> exception=RuntimeError("Task <Task pending name='Task-34' coro=<CollaborationSystem.pipeline() running at co/main.py:62>> got Future <Future pending> attached to a different loop")>
Traceback (most recent call last):
  File "co/main.py", line 62, in pipeline
    base_data_dict = await self.base_data_retriever()
  File "/home/nvidia/mydisk/gzh/projects/cosense/co/baseDataRetriever.py", line 51, in __call__
    data_dict[CONFIG['id']] = await self.get_ego_data()
  File "/home/nvidia/mydisk/gzh/projects/cosense/co/baseDataRetriever.py", line 14, in get_ego_data
    "lidar_np": await agent_server.wait_ego_pcd(),
  File "/home/nvidia/mydisk/gzh/projects/cosense/co/server.py", line 150, in wait_ego_pcd
    await self.ego_pcd.wait()
  File "/home/nvidia/mydisk/gzh/projects/cosense/co/utils.py", line 37, in wait
    await self._wait_condition(timeout)
  File "/home/nvidia/mydisk/gzh/projects/cosense/co/utils.py", line 64, in _wait_condition
    await self._condition.wait_for(lambda: self._value is not None)
  File "/home/nvidia/mydisk/miniconda3/envs/rospy/lib/python3.8/asyncio/locks.py", line 400, in wait_for
    await self.wait()
  File "/home/nvidia/mydisk/miniconda3/envs/rospy/lib/python3.8/asyncio/locks.py", line 373, in wait
    await fut
RuntimeError: Task <Task pending name='Task-34' coro=<CollaborationSystem.pipeline() running at co/main.py:62>> got Future <Future pending> attached to a different loop
2025-03-16 01:33:05,204 - ROS - INFO - 收到点云数据: 100 个点
2025-03-16 01:33:05,399 - asyncio - ERROR - Task exception was never retrieved
future: <Task finished name='Task-36' coro=<CollaborationSystem.pipeline() done, defined at co/main.py:61> exception=RuntimeError("Task <Task pending name='Task-36' coro=<CollaborationSystem.pipeline() running at co/main.py:62>> got Future <Future pending> attached to a different loop")>
Traceback (most recent call last):
  File "co/main.py", line 62, in pipeline
    base_data_dict = await self.base_data_retriever()
  File "/home/nvidia/mydisk/gzh/projects/cosense/co/baseDataRetriever.py", line 51, in __call__
    data_dict[CONFIG['id']] = await self.get_ego_data()
  File "/home/nvidia/mydisk/gzh/projects/cosense/co/baseDataRetriever.py", line 14, in get_ego_data
    "lidar_np": await agent_server.wait_ego_pcd(),
  File "/home/nvidia/mydisk/gzh/projects/cosense/co/server.py", line 150, in wait_ego_pcd
    await self.ego_pcd.wait()
  File "/home/nvidia/mydisk/gzh/projects/cosense/co/utils.py", line 37, in wait
    await self._wait_condition(timeout)
  File "/home/nvidia/mydisk/gzh/projects/cosense/co/utils.py", line 64, in _wait_condition
    await self._condition.wait_for(lambda: self._value is not None)
  File "/home/nvidia/mydisk/miniconda3/envs/rospy/lib/python3.8/asyncio/locks.py", line 400, in wait_for
    await self.wait()
  File "/home/nvidia/mydisk/miniconda3/envs/rospy/lib/python3.8/asyncio/locks.py", line 373, in wait
    await fut
RuntimeError: Task <Task pending name='Task-36' coro=<CollaborationSystem.pipeline() running at co/main.py:62>> got Future <Future pending> attached to a different loop
2025-03-16 01:33:06,204 - ROS - INFO - 收到点云数据: 100 个点
2025-03-16 01:33:06,400 - asyncio - ERROR - Task exception was never retrieved
future: <Task finished name='Task-38' coro=<CollaborationSystem.pipeline() done, defined at co/main.py:61> exception=RuntimeError("Task <Task pending name='Task-38' coro=<CollaborationSystem.pipeline() running at co/main.py:62>> got Future <Future pending> attached to a different loop")>
Traceback (most recent call last):
  File "co/main.py", line 62, in pipeline
    base_data_dict = await self.base_data_retriever()
  File "/home/nvidia/mydisk/gzh/projects/cosense/co/baseDataRetriever.py", line 51, in __call__
    data_dict[CONFIG['id']] = await self.get_ego_data()
  File "/home/nvidia/mydisk/gzh/projects/cosense/co/baseDataRetriever.py", line 14, in get_ego_data
    "lidar_np": await agent_server.wait_ego_pcd(),
  File "/home/nvidia/mydisk/gzh/projects/cosense/co/server.py", line 150, in wait_ego_pcd
    await self.ego_pcd.wait()
  File "/home/nvidia/mydisk/gzh/projects/cosense/co/utils.py", line 37, in wait
    await self._wait_condition(timeout)
  File "/home/nvidia/mydisk/gzh/projects/cosense/co/utils.py", line 64, in _wait_condition
    await self._condition.wait_for(lambda: self._value is not None)
  File "/home/nvidia/mydisk/miniconda3/envs/rospy/lib/python3.8/asyncio/locks.py", line 400, in wait_for
    await self.wait()
  File "/home/nvidia/mydisk/miniconda3/envs/rospy/lib/python3.8/asyncio/locks.py", line 373, in wait
    await fut
RuntimeError: Task <Task pending name='Task-38' coro=<CollaborationSystem.pipeline() running at co/main.py:62>> got Future <Future pending> attached to a different loop
2025-03-16 01:33:07,202 - ROS - INFO - 收到点云数据: 100 个点
2025-03-16 01:33:07,402 - asyncio - ERROR - Task exception was never retrieved
future: <Task finished name='Task-40' coro=<CollaborationSystem.pipeline() done, defined at co/main.py:61> exception=RuntimeError("Task <Task pending name='Task-40' coro=<CollaborationSystem.pipeline() running at co/main.py:62>> got Future <Future pending> attached to a different loop")>
Traceback (most recent call last):
  File "co/main.py", line 62, in pipeline
    base_data_dict = await self.base_data_retriever()
  File "/home/nvidia/mydisk/gzh/projects/cosense/co/baseDataRetriever.py", line 51, in __call__
    data_dict[CONFIG['id']] = await self.get_ego_data()
  File "/home/nvidia/mydisk/gzh/projects/cosense/co/baseDataRetriever.py", line 14, in get_ego_data
    "lidar_np": await agent_server.wait_ego_pcd(),
  File "/home/nvidia/mydisk/gzh/projects/cosense/co/server.py", line 150, in wait_ego_pcd
    await self.ego_pcd.wait()
  File "/home/nvidia/mydisk/gzh/projects/cosense/co/utils.py", line 37, in wait
    await self._wait_condition(timeout)
  File "/home/nvidia/mydisk/gzh/projects/cosense/co/utils.py", line 64, in _wait_condition
    await self._condition.wait_for(lambda: self._value is not None)
  File "/home/nvidia/mydisk/miniconda3/envs/rospy/lib/python3.8/asyncio/locks.py", line 400, in wait_for
    await self.wait()
  File "/home/nvidia/mydisk/miniconda3/envs/rospy/lib/python3.8/asyncio/locks.py", line 373, in wait
    await fut
RuntimeError: Task <Task pending name='Task-40' coro=<CollaborationSystem.pipeline() running at co/main.py:62>> got Future <Future pending> attached to a different loop
2025-03-16 01:33:08,203 - ROS - INFO - 收到点云数据: 100 个点
2025-03-16 01:33:08,404 - asyncio - ERROR - Task exception was never retrieved
future: <Task finished name='Task-42' coro=<CollaborationSystem.pipeline() done, defined at co/main.py:61> exception=RuntimeError("Task <Task pending name='Task-42' coro=<CollaborationSystem.pipeline() running at co/main.py:62>> got Future <Future pending> attached to a different loop")>
Traceback (most recent call last):
  File "co/main.py", line 62, in pipeline
    base_data_dict = await self.base_data_retriever()
  File "/home/nvidia/mydisk/gzh/projects/cosense/co/baseDataRetriever.py", line 51, in __call__
    data_dict[CONFIG['id']] = await self.get_ego_data()
  File "/home/nvidia/mydisk/gzh/projects/cosense/co/baseDataRetriever.py", line 14, in get_ego_data
    "lidar_np": await agent_server.wait_ego_pcd(),
  File "/home/nvidia/mydisk/gzh/projects/cosense/co/server.py", line 150, in wait_ego_pcd
    await self.ego_pcd.wait()
  File "/home/nvidia/mydisk/gzh/projects/cosense/co/utils.py", line 37, in wait
    await self._wait_condition(timeout)
  File "/home/nvidia/mydisk/gzh/projects/cosense/co/utils.py", line 64, in _wait_condition
    await self._condition.wait_for(lambda: self._value is not None)
  File "/home/nvidia/mydisk/miniconda3/envs/rospy/lib/python3.8/asyncio/locks.py", line 400, in wait_for
    await self.wait()
  File "/home/nvidia/mydisk/miniconda3/envs/rospy/lib/python3.8/asyncio/locks.py", line 373, in wait
    await fut
RuntimeError: Task <Task pending name='Task-42' coro=<CollaborationSystem.pipeline() running at co/main.py:62>> got Future <Future pending> attached to a different loop
2025-03-16 01:33:09,204 - ROS - INFO - 收到点云数据: 100 个点
2025-03-16 01:33:09,407 - asyncio - ERROR - Task exception was never retrieved
future: <Task finished name='Task-44' coro=<CollaborationSystem.pipeline() done, defined at co/main.py:61> exception=RuntimeError("Task <Task pending name='Task-44' coro=<CollaborationSystem.pipeline() running at co/main.py:62>> got Future <Future pending> attached to a different loop")>
Traceback (most recent call last):
  File "co/main.py", line 62, in pipeline
    base_data_dict = await self.base_data_retriever()
  File "/home/nvidia/mydisk/gzh/projects/cosense/co/baseDataRetriever.py", line 51, in __call__
    data_dict[CONFIG['id']] = await self.get_ego_data()
  File "/home/nvidia/mydisk/gzh/projects/cosense/co/baseDataRetriever.py", line 14, in get_ego_data
    "lidar_np": await agent_server.wait_ego_pcd(),
  File "/home/nvidia/mydisk/gzh/projects/cosense/co/server.py", line 150, in wait_ego_pcd
    await self.ego_pcd.wait()
  File "/home/nvidia/mydisk/gzh/projects/cosense/co/utils.py", line 37, in wait
    await self._wait_condition(timeout)
  File "/home/nvidia/mydisk/gzh/projects/cosense/co/utils.py", line 64, in _wait_condition
    await self._condition.wait_for(lambda: self._value is not None)
  File "/home/nvidia/mydisk/miniconda3/envs/rospy/lib/python3.8/asyncio/locks.py", line 400, in wait_for
    await self.wait()
  File "/home/nvidia/mydisk/miniconda3/envs/rospy/lib/python3.8/asyncio/locks.py", line 373, in wait
    await fut
RuntimeError: Task <Task pending name='Task-44' coro=<CollaborationSystem.pipeline() running at co/main.py:62>> got Future <Future pending> attached to a different loop
2025-03-16 01:33:10,204 - ROS - INFO - 收到点云数据: 100 个点
2025-03-16 01:33:10,409 - asyncio - ERROR - Task exception was never retrieved
future: <Task finished name='Task-46' coro=<CollaborationSystem.pipeline() done, defined at co/main.py:61> exception=RuntimeError("Task <Task pending name='Task-46' coro=<CollaborationSystem.pipeline() running at co/main.py:62>> got Future <Future pending> attached to a different loop")>
Traceback (most recent call last):
  File "co/main.py", line 62, in pipeline
    base_data_dict = await self.base_data_retriever()
  File "/home/nvidia/mydisk/gzh/projects/cosense/co/baseDataRetriever.py", line 51, in __call__
    data_dict[CONFIG['id']] = await self.get_ego_data()
  File "/home/nvidia/mydisk/gzh/projects/cosense/co/baseDataRetriever.py", line 14, in get_ego_data
    "lidar_np": await agent_server.wait_ego_pcd(),
  File "/home/nvidia/mydisk/gzh/projects/cosense/co/server.py", line 150, in wait_ego_pcd
    await self.ego_pcd.wait()
  File "/home/nvidia/mydisk/gzh/projects/cosense/co/utils.py", line 37, in wait
    await self._wait_condition(timeout)
  File "/home/nvidia/mydisk/gzh/projects/cosense/co/utils.py", line 64, in _wait_condition
    await self._condition.wait_for(lambda: self._value is not None)
  File "/home/nvidia/mydisk/miniconda3/envs/rospy/lib/python3.8/asyncio/locks.py", line 400, in wait_for
    await self.wait()
  File "/home/nvidia/mydisk/miniconda3/envs/rospy/lib/python3.8/asyncio/locks.py", line 373, in wait
    await fut
RuntimeError: Task <Task pending name='Task-46' coro=<CollaborationSystem.pipeline() running at co/main.py:62>> got Future <Future pending> attached to a different loop
2025-03-16 01:33:11,204 - ROS - INFO - 收到点云数据: 100 个点
2025-03-16 01:33:11,411 - asyncio - ERROR - Task exception was never retrieved
future: <Task finished name='Task-48' coro=<CollaborationSystem.pipeline() done, defined at co/main.py:61> exception=RuntimeError("Task <Task pending name='Task-48' coro=<CollaborationSystem.pipeline() running at co/main.py:62>> got Future <Future pending> attached to a different loop")>
Traceback (most recent call last):
  File "co/main.py", line 62, in pipeline
    base_data_dict = await self.base_data_retriever()
  File "/home/nvidia/mydisk/gzh/projects/cosense/co/baseDataRetriever.py", line 51, in __call__
    data_dict[CONFIG['id']] = await self.get_ego_data()
  File "/home/nvidia/mydisk/gzh/projects/cosense/co/baseDataRetriever.py", line 14, in get_ego_data
    "lidar_np": await agent_server.wait_ego_pcd(),
  File "/home/nvidia/mydisk/gzh/projects/cosense/co/server.py", line 150, in wait_ego_pcd
    await self.ego_pcd.wait()
  File "/home/nvidia/mydisk/gzh/projects/cosense/co/utils.py", line 37, in wait
    await self._wait_condition(timeout)
  File "/home/nvidia/mydisk/gzh/projects/cosense/co/utils.py", line 64, in _wait_condition
    await self._condition.wait_for(lambda: self._value is not None)
  File "/home/nvidia/mydisk/miniconda3/envs/rospy/lib/python3.8/asyncio/locks.py", line 400, in wait_for
    await self.wait()
  File "/home/nvidia/mydisk/miniconda3/envs/rospy/lib/python3.8/asyncio/locks.py", line 373, in wait
    await fut
RuntimeError: Task <Task pending name='Task-48' coro=<CollaborationSystem.pipeline() running at co/main.py:62>> got Future <Future pending> attached to a different loop
2025-03-16 01:33:12,203 - ROS - INFO - 收到点云数据: 100 个点
2025-03-16 01:33:12,413 - asyncio - ERROR - Task exception was never retrieved
future: <Task finished name='Task-50' coro=<CollaborationSystem.pipeline() done, defined at co/main.py:61> exception=RuntimeError("Task <Task pending name='Task-50' coro=<CollaborationSystem.pipeline() running at co/main.py:62>> got Future <Future pending> attached to a different loop")>
Traceback (most recent call last):
  File "co/main.py", line 62, in pipeline
    base_data_dict = await self.base_data_retriever()
  File "/home/nvidia/mydisk/gzh/projects/cosense/co/baseDataRetriever.py", line 51, in __call__
    data_dict[CONFIG['id']] = await self.get_ego_data()
  File "/home/nvidia/mydisk/gzh/projects/cosense/co/baseDataRetriever.py", line 14, in get_ego_data
    "lidar_np": await agent_server.wait_ego_pcd(),
  File "/home/nvidia/mydisk/gzh/projects/cosense/co/server.py", line 150, in wait_ego_pcd
    await self.ego_pcd.wait()
  File "/home/nvidia/mydisk/gzh/projects/cosense/co/utils.py", line 37, in wait
    await self._wait_condition(timeout)
  File "/home/nvidia/mydisk/gzh/projects/cosense/co/utils.py", line 64, in _wait_condition
    await self._condition.wait_for(lambda: self._value is not None)
  File "/home/nvidia/mydisk/miniconda3/envs/rospy/lib/python3.8/asyncio/locks.py", line 400, in wait_for
    await self.wait()
  File "/home/nvidia/mydisk/miniconda3/envs/rospy/lib/python3.8/asyncio/locks.py", line 373, in wait
    await fut
RuntimeError: Task <Task pending name='Task-50' coro=<CollaborationSystem.pipeline() running at co/main.py:62>> got Future <Future pending> attached to a different loop
2025-03-16 01:33:13,203 - ROS - INFO - 收到点云数据: 100 个点
2025-03-16 01:33:13,415 - asyncio - ERROR - Task exception was never retrieved
future: <Task finished name='Task-52' coro=<CollaborationSystem.pipeline() done, defined at co/main.py:61> exception=RuntimeError("Task <Task pending name='Task-52' coro=<CollaborationSystem.pipeline() running at co/main.py:62>> got Future <Future pending> attached to a different loop")>
Traceback (most recent call last):
  File "co/main.py", line 62, in pipeline
    base_data_dict = await self.base_data_retriever()
  File "/home/nvidia/mydisk/gzh/projects/cosense/co/baseDataRetriever.py", line 51, in __call__
    data_dict[CONFIG['id']] = await self.get_ego_data()
  File "/home/nvidia/mydisk/gzh/projects/cosense/co/baseDataRetriever.py", line 14, in get_ego_data
    "lidar_np": await agent_server.wait_ego_pcd(),
  File "/home/nvidia/mydisk/gzh/projects/cosense/co/server.py", line 150, in wait_ego_pcd
    await self.ego_pcd.wait()
  File "/home/nvidia/mydisk/gzh/projects/cosense/co/utils.py", line 37, in wait
    await self._wait_condition(timeout)
  File "/home/nvidia/mydisk/gzh/projects/cosense/co/utils.py", line 64, in _wait_condition
    await self._condition.wait_for(lambda: self._value is not None)
  File "/home/nvidia/mydisk/miniconda3/envs/rospy/lib/python3.8/asyncio/locks.py", line 400, in wait_for
    await self.wait()
  File "/home/nvidia/mydisk/miniconda3/envs/rospy/lib/python3.8/asyncio/locks.py", line 373, in wait
    await fut
RuntimeError: Task <Task pending name='Task-52' coro=<CollaborationSystem.pipeline() running at co/main.py:62>> got Future <Future pending> attached to a different loop
